<mujoco>
    <size njmax="3000" nconmax="1000"/>
    <option timestep="0.002"/>
    <default>
        <geom condim="6" density="1" rgba="1 0 0 1"/>
        <joint damping=".001"/>
        <motor ctrlrange="-1 1" ctrllimited="true" forcerange="-.05 .05" forcelimited="true"/>
        <velocity ctrlrange="-1 1" ctrllimited="true" forcerange="-.05 .05" forcelimited="true"/>
        <site size="0.032" type="sphere"/>
    </default>
    <worldbody>
        <light name="top" pos="0 0 1"/>
        <geom name="floor" size="5 5 0.1" type="plane" condim="6"/>
        <body name="robot" pos="0 0 .1">
            <camera name="vision" pos="0 0 .15" xyaxes="0 -1 0 .4 0 1" fovy="90"/>
            <joint type="slide" axis="1 0 0" name="x" damping="0.01"/>
            <joint type="slide" axis="0 1 0" name="y" damping="0.01"/>
            <joint type="hinge" axis="0 0 1" name="z" damping="0.005"/>
            <geom name="robot_geom" type="sphere" size=".1" friction="1 0.01 0.01"/>
            <geom name="pointarrow" pos="0.1 0 0" size="0.05 0.05 0.05" type="box"/>
            <site name="robot" rgba="1 0 0 .1"/>
        </body>
        <!-- Add objects in front of the robot -->
        <body name="object0" pos="1 0 0.1">
            <geom name="object0_geom" type="box" size="0.1 0.1 0.1" rgba="0 1 0 1"/>
        </body>
        <body name="object1" pos="2 0 0.1">
            <geom name="object1_geom" type="box" size="0.1 0.1 0.1" rgba="0 1 0 1"/>
        </body>
        <!-- Add more objects as needed -->
    </worldbody>
    <!-- Rest of your XML file remains the same -->
</mujoco>
